[2024-05-19T16:15:23.897+0000] {local_task_job_runner.py:120} INFO - ::group::Pre task execution logs
[2024-05-19T16:15:23.906+0000] {taskinstance.py:2076} INFO - Dependencies all met for dep_context=non-requeueable deps ti=<TaskInstance: disney_data_pipeline.query_disney_api scheduled__2024-05-19T16:10:00+00:00 [queued]>
[2024-05-19T16:15:23.910+0000] {taskinstance.py:2076} INFO - Dependencies all met for dep_context=requeueable deps ti=<TaskInstance: disney_data_pipeline.query_disney_api scheduled__2024-05-19T16:10:00+00:00 [queued]>
[2024-05-19T16:15:23.911+0000] {taskinstance.py:2306} INFO - Starting attempt 1 of 2
[2024-05-19T16:15:23.918+0000] {taskinstance.py:2330} INFO - Executing <Task(PythonOperator): query_disney_api> on 2024-05-19 16:10:00+00:00
[2024-05-19T16:15:23.922+0000] {warnings.py:110} WARNING - /home/***/.local/lib/python3.12/site-packages/***/task/task_runner/standard_task_runner.py:61: DeprecationWarning: This process (pid=106) is multi-threaded, use of fork() may lead to deadlocks in the child.
  pid = os.fork()

[2024-05-19T16:15:23.924+0000] {standard_task_runner.py:63} INFO - Started process 119 to run task
[2024-05-19T16:15:23.924+0000] {standard_task_runner.py:90} INFO - Running: ['***', 'tasks', 'run', 'disney_data_pipeline', 'query_disney_api', 'scheduled__2024-05-19T16:10:00+00:00', '--job-id', '56', '--raw', '--subdir', 'DAGS_FOLDER/api_disney.py', '--cfg-path', '/tmp/tmpl8amqkl3']
[2024-05-19T16:15:23.927+0000] {standard_task_runner.py:91} INFO - Job 56: Subtask query_disney_api
[2024-05-19T16:15:23.966+0000] {task_command.py:426} INFO - Running <TaskInstance: disney_data_pipeline.query_disney_api scheduled__2024-05-19T16:10:00+00:00 [running]> on host 620090466bc8
[2024-05-19T16:15:24.008+0000] {taskinstance.py:2648} INFO - Exporting env vars: AIRFLOW_CTX_DAG_EMAIL='***@example.com' AIRFLOW_CTX_DAG_OWNER='***' AIRFLOW_CTX_DAG_ID='disney_data_pipeline' AIRFLOW_CTX_TASK_ID='query_disney_api' AIRFLOW_CTX_EXECUTION_DATE='2024-05-19T16:10:00+00:00' AIRFLOW_CTX_TRY_NUMBER='1' AIRFLOW_CTX_DAG_RUN_ID='scheduled__2024-05-19T16:10:00+00:00'
[2024-05-19T16:15:24.010+0000] {taskinstance.py:430} INFO - ::endgroup::
[2024-05-19T16:15:24.652+0000] {base.py:84} INFO - Using connection ID 'aws_s3' for task execution.
[2024-05-19T16:15:24.653+0000] {connection_wrapper.py:384} INFO - AWS Connection (conn_id='aws_s3', conn_type='aws') credentials retrieved from login and password.
[2024-05-19T16:15:24.653+0000] {logging_mixin.py:188} INFO - Error processing data: Either client_type=None or resource_type=None must be provided, not both.
[2024-05-19T16:15:24.653+0000] {taskinstance.py:441} INFO - ::group::Post task execution logs
[2024-05-19T16:15:24.653+0000] {taskinstance.py:2905} ERROR - Task failed with exception
Traceback (most recent call last):
  File "/home/airflow/.local/lib/python3.12/site-packages/airflow/models/taskinstance.py", line 460, in _execute_task
    result = _execute_callable(context=context, **execute_callable_kwargs)
             ^^^^^^^^^^^^^^^^^^^^^^^^^^^^^^^^^^^^^^^^^^^^^^^^^^^^^^^^^^^^^
  File "/home/airflow/.local/lib/python3.12/site-packages/airflow/models/taskinstance.py", line 432, in _execute_callable
    return execute_callable(context=context, **execute_callable_kwargs)
           ^^^^^^^^^^^^^^^^^^^^^^^^^^^^^^^^^^^^^^^^^^^^^^^^^^^^^^^^^^^^
  File "/home/airflow/.local/lib/python3.12/site-packages/airflow/models/baseoperator.py", line 400, in wrapper
    return func(self, *args, **kwargs)
           ^^^^^^^^^^^^^^^^^^^^^^^^^^^
  File "/home/airflow/.local/lib/python3.12/site-packages/airflow/operators/python.py", line 235, in execute
    return_value = self.execute_callable()
                   ^^^^^^^^^^^^^^^^^^^^^^^
  File "/home/airflow/.local/lib/python3.12/site-packages/airflow/operators/python.py", line 252, in execute_callable
    return self.python_callable(*self.op_args, **self.op_kwargs)
           ^^^^^^^^^^^^^^^^^^^^^^^^^^^^^^^^^^^^^^^^^^^^^^^^^^^^^
  File "/opt/airflow/dags/api_disney.py", line 47, in query_disney_api
    raise e  # Re-raise the exception to mark the task as failed
    ^^^^^^^
  File "/opt/airflow/dags/api_disney.py", line 34, in query_disney_api
    conn = aws_hook.get_conn()
           ^^^^^^^^^^^^^^^^^^^
  File "/home/airflow/.local/lib/python3.12/site-packages/airflow/providers/amazon/aws/hooks/base_aws.py", line 762, in get_conn
    return self.conn
           ^^^^^^^^^
  File "/usr/local/lib/python3.12/functools.py", line 995, in __get__
    val = self.func(instance)
          ^^^^^^^^^^^^^^^^^^^
  File "/home/airflow/.local/lib/python3.12/site-packages/airflow/providers/amazon/aws/hooks/base_aws.py", line 720, in conn
    return self.get_resource_type(region_name=self.region_name)
           ^^^^^^^^^^^^^^^^^^^^^^^^^^^^^^^^^^^^^^^^^^^^^^^^^^^^
  File "/home/airflow/.local/lib/python3.12/site-packages/airflow/providers/amazon/aws/hooks/base_aws.py", line 702, in get_resource_type
    service_name = self._resolve_service_name(is_resource_type=True)
                   ^^^^^^^^^^^^^^^^^^^^^^^^^^^^^^^^^^^^^^^^^^^^^^^^^
  File "/home/airflow/.local/lib/python3.12/site-packages/airflow/providers/amazon/aws/hooks/base_aws.py", line 603, in _resolve_service_name
    raise ValueError(
ValueError: Either client_type=None or resource_type=None must be provided, not both.
[2024-05-19T16:15:24.659+0000] {taskinstance.py:1206} INFO - Marking task as UP_FOR_RETRY. dag_id=disney_data_pipeline, task_id=query_disney_api, run_id=scheduled__2024-05-19T16:10:00+00:00, execution_date=20240519T161000, start_date=20240519T161523, end_date=20240519T161524
[2024-05-19T16:15:24.665+0000] {standard_task_runner.py:110} ERROR - Failed to execute job 56 for task query_disney_api (Either client_type=None or resource_type=None must be provided, not both.; 119)
[2024-05-19T16:15:24.697+0000] {local_task_job_runner.py:240} INFO - Task exited with return code 1
[2024-05-19T16:15:24.711+0000] {taskinstance.py:3498} INFO - 0 downstream tasks scheduled from follow-on schedule check
[2024-05-19T16:15:24.711+0000] {local_task_job_runner.py:222} INFO - ::endgroup::
