[2024-05-19T15:56:36.884+0000] {local_task_job_runner.py:120} INFO - ::group::Pre task execution logs
[2024-05-19T15:56:36.891+0000] {taskinstance.py:2076} INFO - Dependencies all met for dep_context=non-requeueable deps ti=<TaskInstance: disney_data_pipeline.transfer_local_to_s3 scheduled__2024-05-19T15:40:00+00:00 [queued]>
[2024-05-19T15:56:36.894+0000] {taskinstance.py:2076} INFO - Dependencies all met for dep_context=requeueable deps ti=<TaskInstance: disney_data_pipeline.transfer_local_to_s3 scheduled__2024-05-19T15:40:00+00:00 [queued]>
[2024-05-19T15:56:36.894+0000] {taskinstance.py:2306} INFO - Starting attempt 2 of 2
[2024-05-19T15:56:36.899+0000] {taskinstance.py:2330} INFO - Executing <Task(LocalFilesystemToS3Operator): transfer_local_to_s3> on 2024-05-19 15:40:00+00:00
[2024-05-19T15:56:36.903+0000] {warnings.py:110} WARNING - /home/***/.local/lib/python3.12/site-packages/***/task/task_runner/standard_task_runner.py:61: DeprecationWarning: This process (pid=808) is multi-threaded, use of fork() may lead to deadlocks in the child.
  pid = os.fork()

[2024-05-19T15:56:36.904+0000] {standard_task_runner.py:63} INFO - Started process 815 to run task
[2024-05-19T15:56:36.904+0000] {standard_task_runner.py:90} INFO - Running: ['***', 'tasks', 'run', 'disney_data_pipeline', 'transfer_local_to_s3', 'scheduled__2024-05-19T15:40:00+00:00', '--job-id', '33', '--raw', '--subdir', 'DAGS_FOLDER/api_disney.py', '--cfg-path', '/tmp/tmpl9bvoc_z']
[2024-05-19T15:56:36.905+0000] {standard_task_runner.py:91} INFO - Job 33: Subtask transfer_local_to_s3
[2024-05-19T15:56:36.925+0000] {task_command.py:426} INFO - Running <TaskInstance: disney_data_pipeline.transfer_local_to_s3 scheduled__2024-05-19T15:40:00+00:00 [running]> on host 620090466bc8
[2024-05-19T15:56:36.955+0000] {taskinstance.py:2648} INFO - Exporting env vars: AIRFLOW_CTX_DAG_EMAIL='***@example.com' AIRFLOW_CTX_DAG_OWNER='***' AIRFLOW_CTX_DAG_ID='disney_data_pipeline' AIRFLOW_CTX_TASK_ID='transfer_local_to_s3' AIRFLOW_CTX_EXECUTION_DATE='2024-05-19T15:40:00+00:00' AIRFLOW_CTX_TRY_NUMBER='2' AIRFLOW_CTX_DAG_RUN_ID='scheduled__2024-05-19T15:40:00+00:00'
[2024-05-19T15:56:36.956+0000] {taskinstance.py:430} INFO - ::endgroup::
[2024-05-19T15:56:36.966+0000] {base.py:84} INFO - Using connection ID 'aws_s3' for task execution.
[2024-05-19T15:56:36.966+0000] {connection_wrapper.py:384} INFO - AWS Connection (conn_id='aws_s3', conn_type='aws') credentials retrieved from login and password.
[2024-05-19T15:56:37.780+0000] {taskinstance.py:441} INFO - ::group::Post task execution logs
[2024-05-19T15:56:37.782+0000] {taskinstance.py:2905} ERROR - Task failed with exception
Traceback (most recent call last):
  File "/home/airflow/.local/lib/python3.12/site-packages/airflow/models/taskinstance.py", line 465, in _execute_task
    result = _execute_callable(context=context, **execute_callable_kwargs)
             ^^^^^^^^^^^^^^^^^^^^^^^^^^^^^^^^^^^^^^^^^^^^^^^^^^^^^^^^^^^^^
  File "/home/airflow/.local/lib/python3.12/site-packages/airflow/models/taskinstance.py", line 432, in _execute_callable
    return execute_callable(context=context, **execute_callable_kwargs)
           ^^^^^^^^^^^^^^^^^^^^^^^^^^^^^^^^^^^^^^^^^^^^^^^^^^^^^^^^^^^^
  File "/home/airflow/.local/lib/python3.12/site-packages/airflow/models/baseoperator.py", line 400, in wrapper
    return func(self, *args, **kwargs)
           ^^^^^^^^^^^^^^^^^^^^^^^^^^^
  File "/home/airflow/.local/lib/python3.12/site-packages/airflow/providers/amazon/aws/transfers/local_to_s3.py", line 100, in execute
    s3_hook.load_file(
  File "/home/airflow/.local/lib/python3.12/site-packages/airflow/providers/amazon/aws/hooks/s3.py", line 135, in wrapper
    return func(*bound_args.args, **bound_args.kwargs)
           ^^^^^^^^^^^^^^^^^^^^^^^^^^^^^^^^^^^^^^^^^^^
  File "/home/airflow/.local/lib/python3.12/site-packages/airflow/providers/amazon/aws/hooks/s3.py", line 89, in wrapper
    return func(*bound_args.args, **bound_args.kwargs)
           ^^^^^^^^^^^^^^^^^^^^^^^^^^^^^^^^^^^^^^^^^^^
  File "/home/airflow/.local/lib/python3.12/site-packages/airflow/providers/amazon/aws/hooks/s3.py", line 1083, in load_file
    raise ValueError(f"The key {key} already exists.")
ValueError: The key bronze/ already exists.
[2024-05-19T15:56:37.806+0000] {taskinstance.py:1206} INFO - Marking task as FAILED. dag_id=disney_data_pipeline, task_id=transfer_local_to_s3, run_id=scheduled__2024-05-19T15:40:00+00:00, execution_date=20240519T154000, start_date=20240519T155636, end_date=20240519T155637
[2024-05-19T15:56:37.842+0000] {standard_task_runner.py:110} ERROR - Failed to execute job 33 for task transfer_local_to_s3 (The key bronze/ already exists.; 815)
[2024-05-19T15:56:37.889+0000] {local_task_job_runner.py:240} INFO - Task exited with return code 1
[2024-05-19T15:56:37.896+0000] {taskinstance.py:3498} INFO - 0 downstream tasks scheduled from follow-on schedule check
[2024-05-19T15:56:37.896+0000] {local_task_job_runner.py:222} INFO - ::endgroup::
