[2024-05-19T16:13:17.033+0000] {local_task_job_runner.py:120} INFO - ::group::Pre task execution logs
[2024-05-19T16:13:17.039+0000] {taskinstance.py:2076} INFO - Dependencies all met for dep_context=non-requeueable deps ti=<TaskInstance: disney_api_to_log.get_disney_data manual__2024-05-19T16:12:15.063069+00:00 [queued]>
[2024-05-19T16:13:17.042+0000] {taskinstance.py:2076} INFO - Dependencies all met for dep_context=requeueable deps ti=<TaskInstance: disney_api_to_log.get_disney_data manual__2024-05-19T16:12:15.063069+00:00 [queued]>
[2024-05-19T16:13:17.042+0000] {taskinstance.py:2306} INFO - Starting attempt 2 of 2
[2024-05-19T16:13:17.047+0000] {taskinstance.py:2330} INFO - Executing <Task(SimpleHttpOperator): get_disney_data> on 2024-05-19 16:12:15.063069+00:00
[2024-05-19T16:13:17.049+0000] {warnings.py:110} WARNING - /home/***/.local/lib/python3.12/site-packages/***/task/task_runner/standard_task_runner.py:61: DeprecationWarning: This process (pid=68) is multi-threaded, use of fork() may lead to deadlocks in the child.
  pid = os.fork()

[2024-05-19T16:13:17.050+0000] {standard_task_runner.py:63} INFO - Started process 69 to run task
[2024-05-19T16:13:17.050+0000] {standard_task_runner.py:90} INFO - Running: ['***', 'tasks', 'run', 'disney_api_to_log', 'get_disney_data', 'manual__2024-05-19T16:12:15.063069+00:00', '--job-id', '48', '--raw', '--subdir', 'DAGS_FOLDER/consulta_api.py', '--cfg-path', '/tmp/tmp3x4xq5s2']
[2024-05-19T16:13:17.051+0000] {standard_task_runner.py:91} INFO - Job 48: Subtask get_disney_data
[2024-05-19T16:13:17.066+0000] {task_command.py:426} INFO - Running <TaskInstance: disney_api_to_log.get_disney_data manual__2024-05-19T16:12:15.063069+00:00 [running]> on host 620090466bc8
[2024-05-19T16:13:17.092+0000] {taskinstance.py:2648} INFO - Exporting env vars: AIRFLOW_CTX_DAG_OWNER='***' AIRFLOW_CTX_DAG_ID='disney_api_to_log' AIRFLOW_CTX_TASK_ID='get_disney_data' AIRFLOW_CTX_EXECUTION_DATE='2024-05-19T16:12:15.063069+00:00' AIRFLOW_CTX_TRY_NUMBER='2' AIRFLOW_CTX_DAG_RUN_ID='manual__2024-05-19T16:12:15.063069+00:00'
[2024-05-19T16:13:17.092+0000] {taskinstance.py:430} INFO - ::endgroup::
[2024-05-19T16:13:17.098+0000] {http.py:169} INFO - Calling HTTP method
[2024-05-19T16:13:17.101+0000] {base.py:84} INFO - Using connection ID 'disney_api' for task execution.
[2024-05-19T16:13:17.104+0000] {base.py:84} INFO - Using connection ID 'disney_api' for task execution.
[2024-05-19T16:13:17.601+0000] {http.py:199} ERROR - HTTP error: Not Found
[2024-05-19T16:13:17.603+0000] {http.py:200} ERROR - <!DOCTYPE html>
<html lang="en">
<head>
<meta charset="utf-8">
<title>Error</title>
</head>
<body>
<pre>Cannot GET /characters</pre>
</body>
</html>

[2024-05-19T16:13:17.604+0000] {taskinstance.py:441} INFO - ::group::Post task execution logs
[2024-05-19T16:13:17.624+0000] {taskinstance.py:2905} ERROR - Task failed with exception
Traceback (most recent call last):
  File "/home/airflow/.local/lib/python3.12/site-packages/airflow/providers/http/hooks/http.py", line 197, in check_response
    response.raise_for_status()
  File "/home/airflow/.local/lib/python3.12/site-packages/requests/models.py", line 1021, in raise_for_status
    raise HTTPError(http_error_msg, response=self)
requests.exceptions.HTTPError: 404 Client Error: Not Found for url: https://api.disneyapi.dev/characters

During handling of the above exception, another exception occurred:

Traceback (most recent call last):
  File "/home/airflow/.local/lib/python3.12/site-packages/airflow/models/taskinstance.py", line 465, in _execute_task
    result = _execute_callable(context=context, **execute_callable_kwargs)
             ^^^^^^^^^^^^^^^^^^^^^^^^^^^^^^^^^^^^^^^^^^^^^^^^^^^^^^^^^^^^^
  File "/home/airflow/.local/lib/python3.12/site-packages/airflow/models/taskinstance.py", line 432, in _execute_callable
    return execute_callable(context=context, **execute_callable_kwargs)
           ^^^^^^^^^^^^^^^^^^^^^^^^^^^^^^^^^^^^^^^^^^^^^^^^^^^^^^^^^^^^
  File "/home/airflow/.local/lib/python3.12/site-packages/airflow/models/baseoperator.py", line 400, in wrapper
    return func(self, *args, **kwargs)
           ^^^^^^^^^^^^^^^^^^^^^^^^^^^
  File "/home/airflow/.local/lib/python3.12/site-packages/airflow/providers/http/operators/http.py", line 166, in execute
    return self.execute_sync(context=context)
           ^^^^^^^^^^^^^^^^^^^^^^^^^^^^^^^^^^
  File "/home/airflow/.local/lib/python3.12/site-packages/airflow/providers/http/operators/http.py", line 170, in execute_sync
    response = self.hook.run(self.endpoint, self.data, self.headers, self.extra_options)
               ^^^^^^^^^^^^^^^^^^^^^^^^^^^^^^^^^^^^^^^^^^^^^^^^^^^^^^^^^^^^^^^^^^^^^^^^^
  File "/home/airflow/.local/lib/python3.12/site-packages/airflow/providers/http/hooks/http.py", line 187, in run
    return self.run_and_check(session, prepped_request, extra_options)
           ^^^^^^^^^^^^^^^^^^^^^^^^^^^^^^^^^^^^^^^^^^^^^^^^^^^^^^^^^^^
  File "/home/airflow/.local/lib/python3.12/site-packages/airflow/providers/http/hooks/http.py", line 238, in run_and_check
    self.check_response(response)
  File "/home/airflow/.local/lib/python3.12/site-packages/airflow/providers/http/hooks/http.py", line 201, in check_response
    raise AirflowException(str(response.status_code) + ":" + response.reason)
airflow.exceptions.AirflowException: 404:Not Found
[2024-05-19T16:13:17.631+0000] {taskinstance.py:1206} INFO - Marking task as FAILED. dag_id=disney_api_to_log, task_id=get_disney_data, run_id=manual__2024-05-19T16:12:15.063069+00:00, execution_date=20240519T161215, start_date=20240519T161317, end_date=20240519T161317
[2024-05-19T16:13:17.641+0000] {standard_task_runner.py:110} ERROR - Failed to execute job 48 for task get_disney_data (404:Not Found; 69)
[2024-05-19T16:13:17.661+0000] {local_task_job_runner.py:240} INFO - Task exited with return code 1
[2024-05-19T16:13:17.673+0000] {taskinstance.py:3498} INFO - 0 downstream tasks scheduled from follow-on schedule check
[2024-05-19T16:13:17.674+0000] {local_task_job_runner.py:222} INFO - ::endgroup::
