[2024-05-19T20:26:37.533+0000] {local_task_job_runner.py:120} INFO - ::group::Pre task execution logs
[2024-05-19T20:26:37.551+0000] {taskinstance.py:2076} INFO - Dependencies all met for dep_context=non-requeueable deps ti=<TaskInstance: silver_s3.process_parquet_files scheduled__2023-05-04T00:00:00+00:00 [queued]>
[2024-05-19T20:26:37.567+0000] {taskinstance.py:2076} INFO - Dependencies all met for dep_context=requeueable deps ti=<TaskInstance: silver_s3.process_parquet_files scheduled__2023-05-04T00:00:00+00:00 [queued]>
[2024-05-19T20:26:37.568+0000] {taskinstance.py:2306} INFO - Starting attempt 1 of 2
[2024-05-19T20:26:37.582+0000] {taskinstance.py:2330} INFO - Executing <Task(PythonOperator): process_parquet_files> on 2023-05-04 00:00:00+00:00
[2024-05-19T20:26:37.593+0000] {warnings.py:110} WARNING - /home/***/.local/lib/python3.12/site-packages/***/task/task_runner/standard_task_runner.py:61: DeprecationWarning: This process (pid=707) is multi-threaded, use of fork() may lead to deadlocks in the child.
  pid = os.fork()

[2024-05-19T20:26:37.596+0000] {standard_task_runner.py:63} INFO - Started process 734 to run task
[2024-05-19T20:26:37.596+0000] {standard_task_runner.py:90} INFO - Running: ['***', 'tasks', 'run', 'silver_s3', 'process_parquet_files', 'scheduled__2023-05-04T00:00:00+00:00', '--job-id', '253', '--raw', '--subdir', 'DAGS_FOLDER/silver_s3.py', '--cfg-path', '/tmp/tmp2bjm4ey6']
[2024-05-19T20:26:37.604+0000] {standard_task_runner.py:91} INFO - Job 253: Subtask process_parquet_files
[2024-05-19T20:26:37.688+0000] {task_command.py:426} INFO - Running <TaskInstance: silver_s3.process_parquet_files scheduled__2023-05-04T00:00:00+00:00 [running]> on host 620090466bc8
[2024-05-19T20:26:37.827+0000] {taskinstance.py:2648} INFO - Exporting env vars: AIRFLOW_CTX_DAG_OWNER='***' AIRFLOW_CTX_DAG_ID='silver_s3' AIRFLOW_CTX_TASK_ID='process_parquet_files' AIRFLOW_CTX_EXECUTION_DATE='2023-05-04T00:00:00+00:00' AIRFLOW_CTX_TRY_NUMBER='1' AIRFLOW_CTX_DAG_RUN_ID='scheduled__2023-05-04T00:00:00+00:00'
[2024-05-19T20:26:37.828+0000] {taskinstance.py:430} INFO - ::endgroup::
[2024-05-19T20:26:37.861+0000] {base.py:84} INFO - Using connection ID 'aws_s3' for task execution.
[2024-05-19T20:26:37.863+0000] {connection_wrapper.py:384} INFO - AWS Connection (conn_id='aws_s3', conn_type='aws') credentials retrieved from login and password.
[2024-05-19T20:26:42.586+0000] {logging_mixin.py:188} INFO - No .parquet files found.
[2024-05-19T20:26:42.588+0000] {python.py:237} INFO - Done. Returned value was: None
[2024-05-19T20:26:42.590+0000] {taskinstance.py:441} INFO - ::group::Post task execution logs
[2024-05-19T20:26:42.613+0000] {taskinstance.py:1206} INFO - Marking task as SUCCESS. dag_id=silver_s3, task_id=process_parquet_files, run_id=scheduled__2023-05-04T00:00:00+00:00, execution_date=20230504T000000, start_date=20240519T202637, end_date=20240519T202642
[2024-05-19T20:26:42.647+0000] {local_task_job_runner.py:240} INFO - Task exited with return code 0
[2024-05-19T20:26:42.657+0000] {taskinstance.py:3498} INFO - 0 downstream tasks scheduled from follow-on schedule check
[2024-05-19T20:26:42.657+0000] {local_task_job_runner.py:222} INFO - ::endgroup::
[2024-05-19T20:31:03.246+0000] {local_task_job_runner.py:120} INFO - ::group::Pre task execution logs
[2024-05-19T20:31:03.257+0000] {taskinstance.py:2076} INFO - Dependencies all met for dep_context=non-requeueable deps ti=<TaskInstance: silver_s3.process_parquet_files scheduled__2023-05-04T00:00:00+00:00 [queued]>
[2024-05-19T20:31:03.261+0000] {taskinstance.py:2076} INFO - Dependencies all met for dep_context=requeueable deps ti=<TaskInstance: silver_s3.process_parquet_files scheduled__2023-05-04T00:00:00+00:00 [queued]>
[2024-05-19T20:31:03.261+0000] {taskinstance.py:2306} INFO - Starting attempt 1 of 2
[2024-05-19T20:31:03.268+0000] {taskinstance.py:2330} INFO - Executing <Task(PythonOperator): process_parquet_files> on 2023-05-04 00:00:00+00:00
[2024-05-19T20:31:03.272+0000] {warnings.py:110} WARNING - /home/***/.local/lib/python3.12/site-packages/***/task/task_runner/standard_task_runner.py:61: DeprecationWarning: This process (pid=1101) is multi-threaded, use of fork() may lead to deadlocks in the child.
  pid = os.fork()

[2024-05-19T20:31:03.273+0000] {standard_task_runner.py:63} INFO - Started process 1114 to run task
[2024-05-19T20:31:03.273+0000] {standard_task_runner.py:90} INFO - Running: ['***', 'tasks', 'run', 'silver_s3', 'process_parquet_files', 'scheduled__2023-05-04T00:00:00+00:00', '--job-id', '353', '--raw', '--subdir', 'DAGS_FOLDER/silver_s3.py', '--cfg-path', '/tmp/tmp8lpc97g3']
[2024-05-19T20:31:03.275+0000] {standard_task_runner.py:91} INFO - Job 353: Subtask process_parquet_files
[2024-05-19T20:31:03.320+0000] {task_command.py:426} INFO - Running <TaskInstance: silver_s3.process_parquet_files scheduled__2023-05-04T00:00:00+00:00 [running]> on host 620090466bc8
[2024-05-19T20:31:03.364+0000] {taskinstance.py:2648} INFO - Exporting env vars: AIRFLOW_CTX_DAG_OWNER='***' AIRFLOW_CTX_DAG_ID='silver_s3' AIRFLOW_CTX_TASK_ID='process_parquet_files' AIRFLOW_CTX_EXECUTION_DATE='2023-05-04T00:00:00+00:00' AIRFLOW_CTX_TRY_NUMBER='1' AIRFLOW_CTX_DAG_RUN_ID='scheduled__2023-05-04T00:00:00+00:00'
[2024-05-19T20:31:03.365+0000] {taskinstance.py:430} INFO - ::endgroup::
[2024-05-19T20:31:03.385+0000] {base.py:84} INFO - Using connection ID 'aws_s3' for task execution.
[2024-05-19T20:31:03.390+0000] {connection_wrapper.py:384} INFO - AWS Connection (conn_id='aws_s3', conn_type='aws') credentials retrieved from login and password.
[2024-05-19T20:31:51.540+0000] {taskinstance.py:441} INFO - ::group::Post task execution logs
[2024-05-19T20:31:51.564+0000] {taskinstance.py:2905} ERROR - Task failed with exception
Traceback (most recent call last):
  File "/home/airflow/.local/lib/python3.12/site-packages/boto3/s3/transfer.py", line 371, in upload_file
    future.result()
  File "/home/airflow/.local/lib/python3.12/site-packages/s3transfer/futures.py", line 103, in result
    return self._coordinator.result()
           ^^^^^^^^^^^^^^^^^^^^^^^^^^
  File "/home/airflow/.local/lib/python3.12/site-packages/s3transfer/futures.py", line 266, in result
    raise self._exception
  File "/home/airflow/.local/lib/python3.12/site-packages/s3transfer/tasks.py", line 139, in __call__
    return self._execute_main(kwargs)
           ^^^^^^^^^^^^^^^^^^^^^^^^^^
  File "/home/airflow/.local/lib/python3.12/site-packages/s3transfer/tasks.py", line 162, in _execute_main
    return_value = self._main(**kwargs)
                   ^^^^^^^^^^^^^^^^^^^^
  File "/home/airflow/.local/lib/python3.12/site-packages/s3transfer/upload.py", line 764, in _main
    client.put_object(Bucket=bucket, Key=key, Body=body, **extra_args)
  File "/home/airflow/.local/lib/python3.12/site-packages/botocore/client.py", line 553, in _api_call
    return self._make_api_call(operation_name, kwargs)
           ^^^^^^^^^^^^^^^^^^^^^^^^^^^^^^^^^^^^^^^^^^^
  File "/home/airflow/.local/lib/python3.12/site-packages/botocore/client.py", line 1009, in _make_api_call
    raise error_class(parsed_response, operation_name)
botocore.exceptions.ClientError: An error occurred (BadDigest) when calling the PutObject operation (reached max retries: 4): The Content-MD5 you specified did not match what we received.

During handling of the above exception, another exception occurred:

Traceback (most recent call last):
  File "/home/airflow/.local/lib/python3.12/site-packages/airflow/models/taskinstance.py", line 465, in _execute_task
    result = _execute_callable(context=context, **execute_callable_kwargs)
             ^^^^^^^^^^^^^^^^^^^^^^^^^^^^^^^^^^^^^^^^^^^^^^^^^^^^^^^^^^^^^
  File "/home/airflow/.local/lib/python3.12/site-packages/airflow/models/taskinstance.py", line 432, in _execute_callable
    return execute_callable(context=context, **execute_callable_kwargs)
           ^^^^^^^^^^^^^^^^^^^^^^^^^^^^^^^^^^^^^^^^^^^^^^^^^^^^^^^^^^^^
  File "/home/airflow/.local/lib/python3.12/site-packages/airflow/models/baseoperator.py", line 400, in wrapper
    return func(self, *args, **kwargs)
           ^^^^^^^^^^^^^^^^^^^^^^^^^^^
  File "/home/airflow/.local/lib/python3.12/site-packages/airflow/operators/python.py", line 235, in execute
    return_value = self.execute_callable()
                   ^^^^^^^^^^^^^^^^^^^^^^^
  File "/home/airflow/.local/lib/python3.12/site-packages/airflow/operators/python.py", line 252, in execute_callable
    return self.python_callable(*self.op_args, **self.op_kwargs)
           ^^^^^^^^^^^^^^^^^^^^^^^^^^^^^^^^^^^^^^^^^^^^^^^^^^^^^
  File "/opt/airflow/dags/silver_s3.py", line 60, in process_parquet_files
    s3_hook.load_file(
  File "/home/airflow/.local/lib/python3.12/site-packages/airflow/providers/amazon/aws/hooks/s3.py", line 135, in wrapper
    return func(*bound_args.args, **bound_args.kwargs)
           ^^^^^^^^^^^^^^^^^^^^^^^^^^^^^^^^^^^^^^^^^^^
  File "/home/airflow/.local/lib/python3.12/site-packages/airflow/providers/amazon/aws/hooks/s3.py", line 89, in wrapper
    return func(*bound_args.args, **bound_args.kwargs)
           ^^^^^^^^^^^^^^^^^^^^^^^^^^^^^^^^^^^^^^^^^^^
  File "/home/airflow/.local/lib/python3.12/site-packages/airflow/providers/amazon/aws/hooks/s3.py", line 1098, in load_file
    client.upload_file(filename, bucket_name, key, ExtraArgs=extra_args, Config=self.transfer_config)
  File "/home/airflow/.local/lib/python3.12/site-packages/boto3/s3/inject.py", line 145, in upload_file
    return transfer.upload_file(
           ^^^^^^^^^^^^^^^^^^^^^
  File "/home/airflow/.local/lib/python3.12/site-packages/boto3/s3/transfer.py", line 377, in upload_file
    raise S3UploadFailedError(
boto3.exceptions.S3UploadFailedError: Failed to upload /tmp/processed_disney_data_20240518T000000.parquet to lake-poseidon/silver/disney_data_20240518T000000.parquet: An error occurred (BadDigest) when calling the PutObject operation (reached max retries: 4): The Content-MD5 you specified did not match what we received.
[2024-05-19T20:31:51.594+0000] {taskinstance.py:1206} INFO - Marking task as UP_FOR_RETRY. dag_id=silver_s3, task_id=process_parquet_files, run_id=scheduled__2023-05-04T00:00:00+00:00, execution_date=20230504T000000, start_date=20240519T203103, end_date=20240519T203151
[2024-05-19T20:31:51.614+0000] {standard_task_runner.py:110} ERROR - Failed to execute job 353 for task process_parquet_files (Failed to upload /tmp/processed_disney_data_20240518T000000.parquet to lake-poseidon/silver/disney_data_20240518T000000.parquet: An error occurred (BadDigest) when calling the PutObject operation (reached max retries: 4): The Content-MD5 you specified did not match what we received.; 1114)
[2024-05-19T20:31:51.660+0000] {local_task_job_runner.py:240} INFO - Task exited with return code 1
[2024-05-19T20:31:51.674+0000] {taskinstance.py:3498} INFO - 0 downstream tasks scheduled from follow-on schedule check
[2024-05-19T20:31:51.675+0000] {local_task_job_runner.py:222} INFO - ::endgroup::
