[2024-05-19T15:55:12.797+0000] {local_task_job_runner.py:120} INFO - ::group::Pre task execution logs
[2024-05-19T15:55:12.803+0000] {taskinstance.py:2076} INFO - Dependencies all met for dep_context=non-requeueable deps ti=<TaskInstance: disney_data_pipeline.transfer_local_to_s3 manual__2024-05-19T15:55:09.409852+00:00 [queued]>
[2024-05-19T15:55:12.806+0000] {taskinstance.py:2076} INFO - Dependencies all met for dep_context=requeueable deps ti=<TaskInstance: disney_data_pipeline.transfer_local_to_s3 manual__2024-05-19T15:55:09.409852+00:00 [queued]>
[2024-05-19T15:55:12.807+0000] {taskinstance.py:2306} INFO - Starting attempt 1 of 2
[2024-05-19T15:55:12.811+0000] {taskinstance.py:2330} INFO - Executing <Task(LocalFilesystemToS3Operator): transfer_local_to_s3> on 2024-05-19 15:55:09.409852+00:00
[2024-05-19T15:55:12.814+0000] {warnings.py:110} WARNING - /home/***/.local/lib/python3.12/site-packages/***/task/task_runner/standard_task_runner.py:61: DeprecationWarning: This process (pid=780) is multi-threaded, use of fork() may lead to deadlocks in the child.
  pid = os.fork()

[2024-05-19T15:55:12.815+0000] {standard_task_runner.py:63} INFO - Started process 784 to run task
[2024-05-19T15:55:12.815+0000] {standard_task_runner.py:90} INFO - Running: ['***', 'tasks', 'run', 'disney_data_pipeline', 'transfer_local_to_s3', 'manual__2024-05-19T15:55:09.409852+00:00', '--job-id', '29', '--raw', '--subdir', 'DAGS_FOLDER/api_disney.py', '--cfg-path', '/tmp/tmp1ars_jat']
[2024-05-19T15:55:12.817+0000] {standard_task_runner.py:91} INFO - Job 29: Subtask transfer_local_to_s3
[2024-05-19T15:55:12.840+0000] {task_command.py:426} INFO - Running <TaskInstance: disney_data_pipeline.transfer_local_to_s3 manual__2024-05-19T15:55:09.409852+00:00 [running]> on host 620090466bc8
[2024-05-19T15:55:12.874+0000] {taskinstance.py:2648} INFO - Exporting env vars: AIRFLOW_CTX_DAG_EMAIL='***@example.com' AIRFLOW_CTX_DAG_OWNER='***' AIRFLOW_CTX_DAG_ID='disney_data_pipeline' AIRFLOW_CTX_TASK_ID='transfer_local_to_s3' AIRFLOW_CTX_EXECUTION_DATE='2024-05-19T15:55:09.409852+00:00' AIRFLOW_CTX_TRY_NUMBER='1' AIRFLOW_CTX_DAG_RUN_ID='manual__2024-05-19T15:55:09.409852+00:00'
[2024-05-19T15:55:12.875+0000] {taskinstance.py:430} INFO - ::endgroup::
[2024-05-19T15:55:12.885+0000] {base.py:84} INFO - Using connection ID 'aws_s3' for task execution.
[2024-05-19T15:55:12.886+0000] {connection_wrapper.py:384} INFO - AWS Connection (conn_id='aws_s3', conn_type='aws') credentials retrieved from login and password.
[2024-05-19T15:55:13.742+0000] {taskinstance.py:441} INFO - ::group::Post task execution logs
[2024-05-19T15:55:13.744+0000] {taskinstance.py:2905} ERROR - Task failed with exception
Traceback (most recent call last):
  File "/home/airflow/.local/lib/python3.12/site-packages/airflow/models/taskinstance.py", line 465, in _execute_task
    result = _execute_callable(context=context, **execute_callable_kwargs)
             ^^^^^^^^^^^^^^^^^^^^^^^^^^^^^^^^^^^^^^^^^^^^^^^^^^^^^^^^^^^^^
  File "/home/airflow/.local/lib/python3.12/site-packages/airflow/models/taskinstance.py", line 432, in _execute_callable
    return execute_callable(context=context, **execute_callable_kwargs)
           ^^^^^^^^^^^^^^^^^^^^^^^^^^^^^^^^^^^^^^^^^^^^^^^^^^^^^^^^^^^^
  File "/home/airflow/.local/lib/python3.12/site-packages/airflow/models/baseoperator.py", line 400, in wrapper
    return func(self, *args, **kwargs)
           ^^^^^^^^^^^^^^^^^^^^^^^^^^^
  File "/home/airflow/.local/lib/python3.12/site-packages/airflow/providers/amazon/aws/transfers/local_to_s3.py", line 100, in execute
    s3_hook.load_file(
  File "/home/airflow/.local/lib/python3.12/site-packages/airflow/providers/amazon/aws/hooks/s3.py", line 135, in wrapper
    return func(*bound_args.args, **bound_args.kwargs)
           ^^^^^^^^^^^^^^^^^^^^^^^^^^^^^^^^^^^^^^^^^^^
  File "/home/airflow/.local/lib/python3.12/site-packages/airflow/providers/amazon/aws/hooks/s3.py", line 89, in wrapper
    return func(*bound_args.args, **bound_args.kwargs)
           ^^^^^^^^^^^^^^^^^^^^^^^^^^^^^^^^^^^^^^^^^^^
  File "/home/airflow/.local/lib/python3.12/site-packages/airflow/providers/amazon/aws/hooks/s3.py", line 1083, in load_file
    raise ValueError(f"The key {key} already exists.")
ValueError: The key bronze/ already exists.
[2024-05-19T15:55:13.763+0000] {taskinstance.py:1206} INFO - Marking task as UP_FOR_RETRY. dag_id=disney_data_pipeline, task_id=transfer_local_to_s3, run_id=manual__2024-05-19T15:55:09.409852+00:00, execution_date=20240519T155509, start_date=20240519T155512, end_date=20240519T155513
[2024-05-19T15:55:13.778+0000] {standard_task_runner.py:110} ERROR - Failed to execute job 29 for task transfer_local_to_s3 (The key bronze/ already exists.; 784)
[2024-05-19T15:55:13.803+0000] {local_task_job_runner.py:240} INFO - Task exited with return code 1
[2024-05-19T15:55:13.815+0000] {taskinstance.py:3498} INFO - 0 downstream tasks scheduled from follow-on schedule check
[2024-05-19T15:55:13.816+0000] {local_task_job_runner.py:222} INFO - ::endgroup::
