[2024-05-19T15:45:44.348+0000] {local_task_job_runner.py:120} INFO - ::group::Pre task execution logs
[2024-05-19T15:45:44.357+0000] {taskinstance.py:2076} INFO - Dependencies all met for dep_context=non-requeueable deps ti=<TaskInstance: disney_data_pipeline.query_disney_api scheduled__2024-05-19T15:40:00+00:00 [queued]>
[2024-05-19T15:45:44.361+0000] {taskinstance.py:2076} INFO - Dependencies all met for dep_context=requeueable deps ti=<TaskInstance: disney_data_pipeline.query_disney_api scheduled__2024-05-19T15:40:00+00:00 [queued]>
[2024-05-19T15:45:44.362+0000] {taskinstance.py:2306} INFO - Starting attempt 1 of 2
[2024-05-19T15:45:44.367+0000] {taskinstance.py:2330} INFO - Executing <Task(PythonOperator): query_disney_api> on 2024-05-19 15:40:00+00:00
[2024-05-19T15:45:44.371+0000] {warnings.py:110} WARNING - /home/***/.local/lib/python3.12/site-packages/***/task/task_runner/standard_task_runner.py:61: DeprecationWarning: This process (pid=617) is multi-threaded, use of fork() may lead to deadlocks in the child.
  pid = os.fork()

[2024-05-19T15:45:44.372+0000] {standard_task_runner.py:63} INFO - Started process 621 to run task
[2024-05-19T15:45:44.372+0000] {standard_task_runner.py:90} INFO - Running: ['***', 'tasks', 'run', 'disney_data_pipeline', 'query_disney_api', 'scheduled__2024-05-19T15:40:00+00:00', '--job-id', '18', '--raw', '--subdir', 'DAGS_FOLDER/api_disney.py', '--cfg-path', '/tmp/tmp4_vu6gx1']
[2024-05-19T15:45:44.374+0000] {standard_task_runner.py:91} INFO - Job 18: Subtask query_disney_api
[2024-05-19T15:45:44.401+0000] {task_command.py:426} INFO - Running <TaskInstance: disney_data_pipeline.query_disney_api scheduled__2024-05-19T15:40:00+00:00 [running]> on host 620090466bc8
[2024-05-19T15:45:44.443+0000] {taskinstance.py:2648} INFO - Exporting env vars: AIRFLOW_CTX_DAG_EMAIL='taciliorodriguez@gmail.com' AIRFLOW_CTX_DAG_OWNER='***' AIRFLOW_CTX_DAG_ID='disney_data_pipeline' AIRFLOW_CTX_TASK_ID='query_disney_api' AIRFLOW_CTX_EXECUTION_DATE='2024-05-19T15:40:00+00:00' AIRFLOW_CTX_TRY_NUMBER='1' AIRFLOW_CTX_DAG_RUN_ID='scheduled__2024-05-19T15:40:00+00:00'
[2024-05-19T15:45:44.444+0000] {taskinstance.py:430} INFO - ::endgroup::
[2024-05-19T15:45:44.950+0000] {taskinstance.py:441} INFO - ::group::Post task execution logs
[2024-05-19T15:45:44.953+0000] {taskinstance.py:2905} ERROR - Task failed with exception
Traceback (most recent call last):
  File "/home/airflow/.local/lib/python3.12/site-packages/requests/models.py", line 971, in json
    return complexjson.loads(self.text, **kwargs)
           ^^^^^^^^^^^^^^^^^^^^^^^^^^^^^^^^^^^^^^
  File "/usr/local/lib/python3.12/json/__init__.py", line 346, in loads
    return _default_decoder.decode(s)
           ^^^^^^^^^^^^^^^^^^^^^^^^^^
  File "/usr/local/lib/python3.12/json/decoder.py", line 337, in decode
    obj, end = self.raw_decode(s, idx=_w(s, 0).end())
               ^^^^^^^^^^^^^^^^^^^^^^^^^^^^^^^^^^^^^^
  File "/usr/local/lib/python3.12/json/decoder.py", line 355, in raw_decode
    raise JSONDecodeError("Expecting value", s, err.value) from None
json.decoder.JSONDecodeError: Expecting value: line 1 column 1 (char 0)

During handling of the above exception, another exception occurred:

Traceback (most recent call last):
  File "/home/airflow/.local/lib/python3.12/site-packages/airflow/models/taskinstance.py", line 465, in _execute_task
    result = _execute_callable(context=context, **execute_callable_kwargs)
             ^^^^^^^^^^^^^^^^^^^^^^^^^^^^^^^^^^^^^^^^^^^^^^^^^^^^^^^^^^^^^
  File "/home/airflow/.local/lib/python3.12/site-packages/airflow/models/taskinstance.py", line 432, in _execute_callable
    return execute_callable(context=context, **execute_callable_kwargs)
           ^^^^^^^^^^^^^^^^^^^^^^^^^^^^^^^^^^^^^^^^^^^^^^^^^^^^^^^^^^^^
  File "/home/airflow/.local/lib/python3.12/site-packages/airflow/models/baseoperator.py", line 400, in wrapper
    return func(self, *args, **kwargs)
           ^^^^^^^^^^^^^^^^^^^^^^^^^^^
  File "/home/airflow/.local/lib/python3.12/site-packages/airflow/operators/python.py", line 235, in execute
    return_value = self.execute_callable()
                   ^^^^^^^^^^^^^^^^^^^^^^^
  File "/home/airflow/.local/lib/python3.12/site-packages/airflow/operators/python.py", line 252, in execute_callable
    return self.python_callable(*self.op_args, **self.op_kwargs)
           ^^^^^^^^^^^^^^^^^^^^^^^^^^^^^^^^^^^^^^^^^^^^^^^^^^^^^
  File "/opt/airflow/dags/api_disney.py", line 24, in query_disney_api
    data = response.json()['data']
           ^^^^^^^^^^^^^^^
  File "/home/airflow/.local/lib/python3.12/site-packages/requests/models.py", line 975, in json
    raise RequestsJSONDecodeError(e.msg, e.doc, e.pos)
requests.exceptions.JSONDecodeError: Expecting value: line 1 column 1 (char 0)
[2024-05-19T15:45:44.981+0000] {taskinstance.py:1206} INFO - Marking task as UP_FOR_RETRY. dag_id=disney_data_pipeline, task_id=query_disney_api, run_id=scheduled__2024-05-19T15:40:00+00:00, execution_date=20240519T154000, start_date=20240519T154544, end_date=20240519T154544
[2024-05-19T15:45:44.999+0000] {standard_task_runner.py:110} ERROR - Failed to execute job 18 for task query_disney_api (Expecting value: line 1 column 1 (char 0); 621)
[2024-05-19T15:45:45.037+0000] {local_task_job_runner.py:240} INFO - Task exited with return code 1
[2024-05-19T15:45:45.049+0000] {taskinstance.py:3498} INFO - 0 downstream tasks scheduled from follow-on schedule check
[2024-05-19T15:45:45.050+0000] {local_task_job_runner.py:222} INFO - ::endgroup::
